<?xml version="1.0" ?>
<!-- =================================================================================== -->
<!-- |    This document was autogenerated by xacro from dog.urdf.xacro                 | -->
<!-- |    EDITING THIS FILE BY HAND IS NOT RECOMMENDED                                 | -->
<!-- =================================================================================== -->
<robot name="dog">
  <!-- ===== base_link ===== -->
  <link name="base_link">
    <visual>
      <origin rpy="0 0 0" xyz="0 0 0"/>
      <geometry>
        <box size="0.475 0.18 0.1"/>
      </geometry>
      <material name="gray">
        <color rgba="0.5 0.5 0.5 1"/>
      </material>
    </visual>
    <collision>
      <origin rpy="0 0 0" xyz="0 0 0"/>
      <geometry>
        <box size="0.475 0.18 0.1"/>
      </geometry>
    </collision>
    <inertial>
      <mass value="5.0"/>
      <inertia ixx="0.1" ixy="0" ixz="0" iyy="0.1" iyz="0" izz="0.1"/>
    </inertial>
  </link>
  <!-- hip -->
  <link name="front_left_hip">
    <visual>
      <origin rpy="0 0 0" xyz="0 0 0"/>
      <geometry>
        <cylinder length="0.05" radius="0.02"/>
      </geometry>
      <material name="black">
        <color rgba="0 0 0 1"/>
      </material>
    </visual>
    <collision>
      <origin rpy="0 0 0" xyz="0 0 0"/>
      <geometry>
        <cylinder length="0.05" radius="0.02"/>
      </geometry>
    </collision>
    <inertial>
      <mass value="0.2"/>
      <inertia ixx="0.001" ixy="0" ixz="0" iyy="0.001" iyz="0" izz="0.001"/>
    </inertial>
  </link>
  <joint name="front_left_hip_joint" type="revolute">
    <parent link="base_link"/>
    <child link="front_left_hip"/>
    <origin rpy="0 0 0" xyz="0.2375 0.09 0"/>
    <axis xyz="0 0 1"/>
    <limit effort="10" lower="-1.57" upper="1.57" velocity="1"/>
  </joint>
  <!-- thigh -->
  <link name="front_left_thigh">
    <visual>
      <origin rpy="0 0 0" xyz="0 0 -0.072"/>
      <geometry>
        <cylinder length="0.144" radius="0.02"/>
      </geometry>
      <material name="blue">
        <color rgba="0 0 1 1"/>
      </material>
    </visual>
    <collision>
      <origin rpy="0 0 0" xyz="0 0 -0.072"/>
      <geometry>
        <cylinder length="0.144" radius="0.02"/>
      </geometry>
    </collision>
    <inertial>
      <mass value="0.2"/>
      <inertia ixx="0.001" ixy="0" ixz="0" iyy="0.001" iyz="0" izz="0.001"/>
    </inertial>
  </link>
  <joint name="front_left_thigh_joint" type="revolute">
    <parent link="front_left_hip"/>
    <child link="front_left_thigh"/>
    <origin rpy="0 0 0" xyz="0 0 0"/>
    <axis xyz="1 0 0"/>
    <limit effort="10" lower="-1.57" upper="1.57" velocity="1"/>
  </joint>
  <!-- shin -->
  <link name="front_left_shin">
    <visual>
      <origin rpy="0 0 0" xyz="0 0 -0.07625"/>
      <geometry>
        <cylinder length="0.1525" radius="0.02"/>
      </geometry>
      <material name="red">
        <color rgba="1 0 0 1"/>
      </material>
    </visual>
    <collision>
      <origin rpy="0 0 0" xyz="0 0 -0.07625"/>
      <geometry>
        <cylinder length="0.1525" radius="0.02"/>
      </geometry>
    </collision>
    <inertial>
      <mass value="0.2"/>
      <inertia ixx="0.001" ixy="0" ixz="0" iyy="0.001" iyz="0" izz="0.001"/>
    </inertial>
  </link>
  <joint name="front_left_shin_joint" type="revolute">
    <parent link="front_left_thigh"/>
    <child link="front_left_shin"/>
    <!-- ставим шарнир в конце бедра -->
    <origin rpy="0 0 0" xyz="0 0 -0.144"/>
    <axis xyz="1 0 0"/>
    <limit effort="10" lower="-1.57" upper="1.57" velocity="1"/>
  </joint>
  <!-- hip -->
  <link name="front_right_hip">
    <visual>
      <origin rpy="0 0 0" xyz="0 0 0"/>
      <geometry>
        <cylinder length="0.05" radius="0.02"/>
      </geometry>
      <material name="black">
        <color rgba="0 0 0 1"/>
      </material>
    </visual>
    <collision>
      <origin rpy="0 0 0" xyz="0 0 0"/>
      <geometry>
        <cylinder length="0.05" radius="0.02"/>
      </geometry>
    </collision>
    <inertial>
      <mass value="0.2"/>
      <inertia ixx="0.001" ixy="0" ixz="0" iyy="0.001" iyz="0" izz="0.001"/>
    </inertial>
  </link>
  <joint name="front_right_hip_joint" type="revolute">
    <parent link="base_link"/>
    <child link="front_right_hip"/>
    <origin rpy="0 0 0" xyz="0.2375 -0.09 0"/>
    <axis xyz="0 0 1"/>
    <limit effort="10" lower="-1.57" upper="1.57" velocity="1"/>
  </joint>
  <!-- thigh -->
  <link name="front_right_thigh">
    <visual>
      <origin rpy="0 0 0" xyz="0 0 -0.072"/>
      <geometry>
        <cylinder length="0.144" radius="0.02"/>
      </geometry>
      <material name="blue">
        <color rgba="0 0 1 1"/>
      </material>
    </visual>
    <collision>
      <origin rpy="0 0 0" xyz="0 0 -0.072"/>
      <geometry>
        <cylinder length="0.144" radius="0.02"/>
      </geometry>
    </collision>
    <inertial>
      <mass value="0.2"/>
      <inertia ixx="0.001" ixy="0" ixz="0" iyy="0.001" iyz="0" izz="0.001"/>
    </inertial>
  </link>
  <joint name="front_right_thigh_joint" type="revolute">
    <parent link="front_right_hip"/>
    <child link="front_right_thigh"/>
    <origin rpy="0 0 0" xyz="0 0 0"/>
    <axis xyz="1 0 0"/>
    <limit effort="10" lower="-1.57" upper="1.57" velocity="1"/>
  </joint>
  <!-- shin -->
  <link name="front_right_shin">
    <visual>
      <origin rpy="0 0 0" xyz="0 0 -0.07625"/>
      <geometry>
        <cylinder length="0.1525" radius="0.02"/>
      </geometry>
      <material name="red">
        <color rgba="1 0 0 1"/>
      </material>
    </visual>
    <collision>
      <origin rpy="0 0 0" xyz="0 0 -0.07625"/>
      <geometry>
        <cylinder length="0.1525" radius="0.02"/>
      </geometry>
    </collision>
    <inertial>
      <mass value="0.2"/>
      <inertia ixx="0.001" ixy="0" ixz="0" iyy="0.001" iyz="0" izz="0.001"/>
    </inertial>
  </link>
  <joint name="front_right_shin_joint" type="revolute">
    <parent link="front_right_thigh"/>
    <child link="front_right_shin"/>
    <!-- ставим шарнир в конце бедра -->
    <origin rpy="0 0 0" xyz="0 0 -0.144"/>
    <axis xyz="1 0 0"/>
    <limit effort="10" lower="-1.57" upper="1.57" velocity="1"/>
  </joint>
  <!-- hip -->
  <link name="rear_left_hip">
    <visual>
      <origin rpy="0 0 0" xyz="0 0 0"/>
      <geometry>
        <cylinder length="0.05" radius="0.02"/>
      </geometry>
      <material name="black">
        <color rgba="0 0 0 1"/>
      </material>
    </visual>
    <collision>
      <origin rpy="0 0 0" xyz="0 0 0"/>
      <geometry>
        <cylinder length="0.05" radius="0.02"/>
      </geometry>
    </collision>
    <inertial>
      <mass value="0.2"/>
      <inertia ixx="0.001" ixy="0" ixz="0" iyy="0.001" iyz="0" izz="0.001"/>
    </inertial>
  </link>
  <joint name="rear_left_hip_joint" type="revolute">
    <parent link="base_link"/>
    <child link="rear_left_hip"/>
    <origin rpy="0 0 0" xyz="-0.2375 0.09 0"/>
    <axis xyz="0 0 1"/>
    <limit effort="10" lower="-1.57" upper="1.57" velocity="1"/>
  </joint>
  <!-- thigh -->
  <link name="rear_left_thigh">
    <visual>
      <origin rpy="0 0 0" xyz="0 0 -0.072"/>
      <geometry>
        <cylinder length="0.144" radius="0.02"/>
      </geometry>
      <material name="blue">
        <color rgba="0 0 1 1"/>
      </material>
    </visual>
    <collision>
      <origin rpy="0 0 0" xyz="0 0 -0.072"/>
      <geometry>
        <cylinder length="0.144" radius="0.02"/>
      </geometry>
    </collision>
    <inertial>
      <mass value="0.2"/>
      <inertia ixx="0.001" ixy="0" ixz="0" iyy="0.001" iyz="0" izz="0.001"/>
    </inertial>
  </link>
  <joint name="rear_left_thigh_joint" type="revolute">
    <parent link="rear_left_hip"/>
    <child link="rear_left_thigh"/>
    <origin rpy="0 0 0" xyz="0 0 0"/>
    <axis xyz="1 0 0"/>
    <limit effort="10" lower="-1.57" upper="1.57" velocity="1"/>
  </joint>
  <!-- shin -->
  <link name="rear_left_shin">
    <visual>
      <origin rpy="0 0 0" xyz="0 0 -0.07625"/>
      <geometry>
        <cylinder length="0.1525" radius="0.02"/>
      </geometry>
      <material name="red">
        <color rgba="1 0 0 1"/>
      </material>
    </visual>
    <collision>
      <origin rpy="0 0 0" xyz="0 0 -0.07625"/>
      <geometry>
        <cylinder length="0.1525" radius="0.02"/>
      </geometry>
    </collision>
    <inertial>
      <mass value="0.2"/>
      <inertia ixx="0.001" ixy="0" ixz="0" iyy="0.001" iyz="0" izz="0.001"/>
    </inertial>
  </link>
  <joint name="rear_left_shin_joint" type="revolute">
    <parent link="rear_left_thigh"/>
    <child link="rear_left_shin"/>
    <!-- ставим шарнир в конце бедра -->
    <origin rpy="0 0 0" xyz="0 0 -0.144"/>
    <axis xyz="1 0 0"/>
    <limit effort="10" lower="-1.57" upper="1.57" velocity="1"/>
  </joint>
  <!-- hip -->
  <link name="rear_right_hip">
    <visual>
      <origin rpy="0 0 0" xyz="0 0 0"/>
      <geometry>
        <cylinder length="0.05" radius="0.02"/>
      </geometry>
      <material name="black">
        <color rgba="0 0 0 1"/>
      </material>
    </visual>
    <collision>
      <origin rpy="0 0 0" xyz="0 0 0"/>
      <geometry>
        <cylinder length="0.05" radius="0.02"/>
      </geometry>
    </collision>
    <inertial>
      <mass value="0.2"/>
      <inertia ixx="0.001" ixy="0" ixz="0" iyy="0.001" iyz="0" izz="0.001"/>
    </inertial>
  </link>
  <joint name="rear_right_hip_joint" type="revolute">
    <parent link="base_link"/>
    <child link="rear_right_hip"/>
    <origin rpy="0 0 0" xyz="-0.2375 -0.09 0"/>
    <axis xyz="0 0 1"/>
    <limit effort="10" lower="-1.57" upper="1.57" velocity="1"/>
  </joint>
  <!-- thigh -->
  <link name="rear_right_thigh">
    <visual>
      <origin rpy="0 0 0" xyz="0 0 -0.072"/>
      <geometry>
        <cylinder length="0.144" radius="0.02"/>
      </geometry>
      <material name="blue">
        <color rgba="0 0 1 1"/>
      </material>
    </visual>
    <collision>
      <origin rpy="0 0 0" xyz="0 0 -0.072"/>
      <geometry>
        <cylinder length="0.144" radius="0.02"/>
      </geometry>
    </collision>
    <inertial>
      <mass value="0.2"/>
      <inertia ixx="0.001" ixy="0" ixz="0" iyy="0.001" iyz="0" izz="0.001"/>
    </inertial>
  </link>
  <joint name="rear_right_thigh_joint" type="revolute">
    <parent link="rear_right_hip"/>
    <child link="rear_right_thigh"/>
    <origin rpy="0 0 0" xyz="0 0 0"/>
    <axis xyz="1 0 0"/>
    <limit effort="10" lower="-1.57" upper="1.57" velocity="1"/>
  </joint>
  <!-- shin -->
  <link name="rear_right_shin">
    <visual>
      <origin rpy="0 0 0" xyz="0 0 -0.07625"/>
      <geometry>
        <cylinder length="0.1525" radius="0.02"/>
      </geometry>
      <material name="red">
        <color rgba="1 0 0 1"/>
      </material>
    </visual>
    <collision>
      <origin rpy="0 0 0" xyz="0 0 -0.07625"/>
      <geometry>
        <cylinder length="0.1525" radius="0.02"/>
      </geometry>
    </collision>
    <inertial>
      <mass value="0.2"/>
      <inertia ixx="0.001" ixy="0" ixz="0" iyy="0.001" iyz="0" izz="0.001"/>
    </inertial>
  </link>
  <joint name="rear_right_shin_joint" type="revolute">
    <parent link="rear_right_thigh"/>
    <child link="rear_right_shin"/>
    <!-- ставим шарнир в конце бедра -->
    <origin rpy="0 0 0" xyz="0 0 -0.144"/>
    <axis xyz="1 0 0"/>
    <limit effort="10" lower="-1.57" upper="1.57" velocity="1"/>
  </joint>
  <!-- ===== ros2_control (интерфейсы суставов) ===== -->
  <!-- Примечание: имя плагина может отличаться в зависимости от установленного пакета (gazebo_ros2_control / gz_ros2_control).
       Если при запуске ros2_control_node увидите pluginlib-ошибку, см. рекомендации ниже. -->
  <ros2_control name="DogSystem" type="system">
    <hardware>
      <!-- частый рабочий вариант для Gazebo Classic; альтернатива: gazebo_ros2_control/DefaultRobotHWSim -->
      <plugin>gazebo_ros2_control/GazeboSystem</plugin>
    </hardware>
    <!-- перечисляем все суставы и интерфейсы -->
    <joint name="front_left_hip_joint">
      <command_interface name="position"/>
      <state_interface name="position"/>
      <state_interface name="velocity"/>
    </joint>
    <joint name="front_left_thigh_joint">
      <command_interface name="position"/>
      <state_interface name="position"/>
      <state_interface name="velocity"/>
    </joint>
    <joint name="front_left_shin_joint">
      <command_interface name="position"/>
      <state_interface name="position"/>
      <state_interface name="velocity"/>
    </joint>
    <joint name="front_right_hip_joint">
      <command_interface name="position"/>
      <state_interface name="position"/>
      <state_interface name="velocity"/>
    </joint>
    <joint name="front_right_thigh_joint">
      <command_interface name="position"/>
      <state_interface name="position"/>
      <state_interface name="velocity"/>
    </joint>
    <joint name="front_right_shin_joint">
      <command_interface name="position"/>
      <state_interface name="position"/>
      <state_interface name="velocity"/>
    </joint>
    <joint name="rear_left_hip_joint">
      <command_interface name="position"/>
      <state_interface name="position"/>
      <state_interface name="velocity"/>
    </joint>
    <joint name="rear_left_thigh_joint">
      <command_interface name="position"/>
      <state_interface name="position"/>
      <state_interface name="velocity"/>
    </joint>
    <joint name="rear_left_shin_joint">
      <command_interface name="position"/>
      <state_interface name="position"/>
      <state_interface name="velocity"/>
    </joint>
    <joint name="rear_right_hip_joint">
      <command_interface name="position"/>
      <state_interface name="position"/>
      <state_interface name="velocity"/>
    </joint>
    <joint name="rear_right_thigh_joint">
      <command_interface name="position"/>
      <state_interface name="position"/>
      <state_interface name="velocity"/>
    </joint>
    <joint name="rear_right_shin_joint">
      <command_interface name="position"/>
      <state_interface name="position"/>
      <state_interface name="velocity"/>
    </joint>
  </ros2_control>
  <!-- ===== Gazebo плагин (привязан к base_link) ===== -->
  <gazebo reference="base_link">
    <plugin filename="libgazebo_ros2_control.so" name="gazebo_ros2_control">
      <!-- namespace и параметр робота; gazebo плагин использует robotParam/robotNamespace -->
      <robotNamespace>/dog</robotNamespace>
      <robotParam>/robot_description</robotParam>
      <!-- robotSimType: согласовать с тем, что прописано в <ros2_control>/<hardware>/<plugin>.
           Если используете Ignition (gz), см. gz_ros2_control вместо gazebo_ros2_control. -->
      <robotSimType>gazebo_ros2_control/GazeboSystem</robotSimType>
    </plugin>
  </gazebo>
</robot>
